[2024-12-31T10:39:06.046+0000] {local_task_job_runner.py:123} INFO - ::group::Pre task execution logs
[2024-12-31T10:39:06.087+0000] {taskinstance.py:2613} INFO - Dependencies all met for dep_context=non-requeueable deps ti=<TaskInstance: de01-final-project-dag.load-and-clean scheduled__2024-12-28T00:00:00+00:00 [queued]>
[2024-12-31T10:39:06.113+0000] {taskinstance.py:2613} INFO - Dependencies all met for dep_context=requeueable deps ti=<TaskInstance: de01-final-project-dag.load-and-clean scheduled__2024-12-28T00:00:00+00:00 [queued]>
[2024-12-31T10:39:06.116+0000] {taskinstance.py:2866} INFO - Starting attempt 4 of 11
[2024-12-31T10:39:06.153+0000] {taskinstance.py:2889} INFO - Executing <Task(PythonOperator): load-and-clean> on 2024-12-28 00:00:00+00:00
[2024-12-31T10:39:06.173+0000] {warnings.py:112} WARNING - /home/***/.local/lib/python3.12/site-packages/***/task/task_runner/standard_task_runner.py:70: DeprecationWarning: This process (pid=254) is multi-threaded, use of fork() may lead to deadlocks in the child.
  pid = os.fork()

[2024-12-31T10:39:06.178+0000] {standard_task_runner.py:72} INFO - Started process 266 to run task
[2024-12-31T10:39:06.177+0000] {standard_task_runner.py:104} INFO - Running: ['***', 'tasks', 'run', 'de01-final-project-dag', 'load-and-clean', 'scheduled__2024-12-28T00:00:00+00:00', '--job-id', '25', '--raw', '--subdir', 'DAGS_FOLDER/dags.py', '--cfg-path', '/tmp/tmp4tbf7d5h']
[2024-12-31T10:39:06.181+0000] {standard_task_runner.py:105} INFO - Job 25: Subtask load-and-clean
[2024-12-31T10:39:06.760+0000] {task_command.py:467} INFO - Running <TaskInstance: de01-final-project-dag.load-and-clean scheduled__2024-12-28T00:00:00+00:00 [running]> on host 864534f4bb16
[2024-12-31T10:39:06.957+0000] {taskinstance.py:3132} INFO - Exporting env vars: AIRFLOW_CTX_DAG_EMAIL='test@***.com' AIRFLOW_CTX_DAG_OWNER='***' AIRFLOW_CTX_DAG_ID='de01-final-project-dag' AIRFLOW_CTX_TASK_ID='load-and-clean' AIRFLOW_CTX_EXECUTION_DATE='2024-12-28T00:00:00+00:00' AIRFLOW_CTX_TRY_NUMBER='4' AIRFLOW_CTX_DAG_RUN_ID='scheduled__2024-12-28T00:00:00+00:00'
[2024-12-31T10:39:06.959+0000] {logging_mixin.py:190} INFO - Task instance is in running state
[2024-12-31T10:39:06.961+0000] {logging_mixin.py:190} INFO -  Previous state of the Task instance: queued
[2024-12-31T10:39:06.962+0000] {logging_mixin.py:190} INFO - Current task name:load-and-clean state:running start_date:2024-12-31 10:39:06.089344+00:00
[2024-12-31T10:39:06.964+0000] {logging_mixin.py:190} INFO - Dag name:de01-final-project-dag and current dag run status:running
[2024-12-31T10:39:06.965+0000] {taskinstance.py:731} INFO - ::endgroup::
[2024-12-31T10:39:07.018+0000] {taskinstance.py:3311} ERROR - Task failed with exception
Traceback (most recent call last):
  File "/home/airflow/.local/lib/python3.12/site-packages/airflow/models/taskinstance.py", line 767, in _execute_task
    result = _execute_callable(context=context, **execute_callable_kwargs)
             ^^^^^^^^^^^^^^^^^^^^^^^^^^^^^^^^^^^^^^^^^^^^^^^^^^^^^^^^^^^^^
  File "/home/airflow/.local/lib/python3.12/site-packages/airflow/models/taskinstance.py", line 733, in _execute_callable
    return ExecutionCallableRunner(
           ^^^^^^^^^^^^^^^^^^^^^^^^
  File "/home/airflow/.local/lib/python3.12/site-packages/airflow/utils/operator_helpers.py", line 252, in run
    return self.func(*args, **kwargs)
           ^^^^^^^^^^^^^^^^^^^^^^^^^^
  File "/home/airflow/.local/lib/python3.12/site-packages/airflow/models/baseoperator.py", line 422, in wrapper
    return func(self, *args, **kwargs)
           ^^^^^^^^^^^^^^^^^^^^^^^^^^^
  File "/home/airflow/.local/lib/python3.12/site-packages/airflow/operators/python.py", line 238, in execute
    return_value = self.execute_callable()
                   ^^^^^^^^^^^^^^^^^^^^^^^
  File "/home/airflow/.local/lib/python3.12/site-packages/airflow/operators/python.py", line 256, in execute_callable
    return runner.run(*self.op_args, **self.op_kwargs)
           ^^^^^^^^^^^^^^^^^^^^^^^^^^^^^^^^^^^^^^^^^^^
  File "/home/airflow/.local/lib/python3.12/site-packages/airflow/utils/operator_helpers.py", line 252, in run
    return self.func(*args, **kwargs)
           ^^^^^^^^^^^^^^^^^^^^^^^^^^
  File "/opt/airflow/dags/dags.py", line 36, in load_and_clean
    raise Exception(f'Script failed with error: {result.stderr}')
Exception: Script failed with error: python: can't open file '/opt/***/nyc-collisions-download-cleanup.py': [Errno 2] No such file or directory

[2024-12-31T10:39:07.053+0000] {logging_mixin.py:190} INFO - Task instance in failure state
[2024-12-31T10:39:07.054+0000] {logging_mixin.py:190} INFO - Task start:2024-12-31 10:39:06.089344+00:00 end:2024-12-31 10:39:07.052207+00:00 duration:0.962863
[2024-12-31T10:39:07.056+0000] {logging_mixin.py:190} INFO - Task:<Task(PythonOperator): load-and-clean> dag:<DAG: de01-final-project-dag> dagrun:<DagRun de01-final-project-dag @ 2024-12-28 00:00:00+00:00: scheduled__2024-12-28T00:00:00+00:00, state:running, queued_at: 2024-12-31 10:35:26.662165+00:00. externally triggered: False>
[2024-12-31T10:39:07.057+0000] {logging_mixin.py:190} INFO - Failure caused by Script failed with error: python: can't open file '/opt/***/nyc-collisions-download-cleanup.py': [Errno 2] No such file or directory
[2024-12-31T10:39:07.059+0000] {taskinstance.py:1225} INFO - Marking task as UP_FOR_RETRY. dag_id=de01-final-project-dag, task_id=load-and-clean, run_id=scheduled__2024-12-28T00:00:00+00:00, execution_date=20241228T000000, start_date=20241231T103906, end_date=20241231T103907
[2024-12-31T10:39:07.102+0000] {taskinstance.py:340} INFO - ::group::Post task execution logs
[2024-12-31T10:39:07.104+0000] {standard_task_runner.py:124} ERROR - Failed to execute job 25 for task load-and-clean (Script failed with error: python: can't open file '/opt/***/nyc-collisions-download-cleanup.py': [Errno 2] No such file or directory
; 266)
Traceback (most recent call last):
  File "/home/airflow/.local/lib/python3.12/site-packages/airflow/task/task_runner/standard_task_runner.py", line 117, in _start_by_fork
    ret = args.func(args, dag=self.dag)
          ^^^^^^^^^^^^^^^^^^^^^^^^^^^^^
  File "/home/airflow/.local/lib/python3.12/site-packages/airflow/cli/cli_config.py", line 49, in command
    return func(*args, **kwargs)
           ^^^^^^^^^^^^^^^^^^^^^
  File "/home/airflow/.local/lib/python3.12/site-packages/airflow/utils/cli.py", line 116, in wrapper
    return f(*args, **kwargs)
           ^^^^^^^^^^^^^^^^^^
  File "/home/airflow/.local/lib/python3.12/site-packages/airflow/cli/commands/task_command.py", line 483, in task_run
    task_return_code = _run_task_by_selected_method(args, _dag, ti)
                       ^^^^^^^^^^^^^^^^^^^^^^^^^^^^^^^^^^^^^^^^^^^^
  File "/home/airflow/.local/lib/python3.12/site-packages/airflow/cli/commands/task_command.py", line 256, in _run_task_by_selected_method
    return _run_raw_task(args, ti)
           ^^^^^^^^^^^^^^^^^^^^^^^
  File "/home/airflow/.local/lib/python3.12/site-packages/airflow/cli/commands/task_command.py", line 341, in _run_raw_task
    return ti._run_raw_task(
           ^^^^^^^^^^^^^^^^^
  File "/home/airflow/.local/lib/python3.12/site-packages/airflow/utils/session.py", line 97, in wrapper
    return func(*args, session=session, **kwargs)
           ^^^^^^^^^^^^^^^^^^^^^^^^^^^^^^^^^^^^^^
  File "/home/airflow/.local/lib/python3.12/site-packages/airflow/models/taskinstance.py", line 3005, in _run_raw_task
    return _run_raw_task(
           ^^^^^^^^^^^^^^
  File "/home/airflow/.local/lib/python3.12/site-packages/airflow/models/taskinstance.py", line 273, in _run_raw_task
    TaskInstance._execute_task_with_callbacks(
  File "/home/airflow/.local/lib/python3.12/site-packages/airflow/models/taskinstance.py", line 3159, in _execute_task_with_callbacks
    result = self._execute_task(context, task_orig)
             ^^^^^^^^^^^^^^^^^^^^^^^^^^^^^^^^^^^^^^
  File "/home/airflow/.local/lib/python3.12/site-packages/airflow/models/taskinstance.py", line 3183, in _execute_task
    return _execute_task(self, context, task_orig)
           ^^^^^^^^^^^^^^^^^^^^^^^^^^^^^^^^^^^^^^^
  File "/home/airflow/.local/lib/python3.12/site-packages/airflow/models/taskinstance.py", line 767, in _execute_task
    result = _execute_callable(context=context, **execute_callable_kwargs)
             ^^^^^^^^^^^^^^^^^^^^^^^^^^^^^^^^^^^^^^^^^^^^^^^^^^^^^^^^^^^^^
  File "/home/airflow/.local/lib/python3.12/site-packages/airflow/models/taskinstance.py", line 733, in _execute_callable
    return ExecutionCallableRunner(
           ^^^^^^^^^^^^^^^^^^^^^^^^
  File "/home/airflow/.local/lib/python3.12/site-packages/airflow/utils/operator_helpers.py", line 252, in run
    return self.func(*args, **kwargs)
           ^^^^^^^^^^^^^^^^^^^^^^^^^^
  File "/home/airflow/.local/lib/python3.12/site-packages/airflow/models/baseoperator.py", line 422, in wrapper
    return func(self, *args, **kwargs)
           ^^^^^^^^^^^^^^^^^^^^^^^^^^^
  File "/home/airflow/.local/lib/python3.12/site-packages/airflow/operators/python.py", line 238, in execute
    return_value = self.execute_callable()
                   ^^^^^^^^^^^^^^^^^^^^^^^
  File "/home/airflow/.local/lib/python3.12/site-packages/airflow/operators/python.py", line 256, in execute_callable
    return runner.run(*self.op_args, **self.op_kwargs)
           ^^^^^^^^^^^^^^^^^^^^^^^^^^^^^^^^^^^^^^^^^^^
  File "/home/airflow/.local/lib/python3.12/site-packages/airflow/utils/operator_helpers.py", line 252, in run
    return self.func(*args, **kwargs)
           ^^^^^^^^^^^^^^^^^^^^^^^^^^
  File "/opt/airflow/dags/dags.py", line 36, in load_and_clean
    raise Exception(f'Script failed with error: {result.stderr}')
Exception: Script failed with error: python: can't open file '/opt/***/nyc-collisions-download-cleanup.py': [Errno 2] No such file or directory

[2024-12-31T10:39:07.164+0000] {local_task_job_runner.py:266} INFO - Task exited with return code 1
[2024-12-31T10:39:07.522+0000] {taskinstance.py:3895} INFO - 0 downstream tasks scheduled from follow-on schedule check
[2024-12-31T10:39:07.527+0000] {local_task_job_runner.py:245} INFO - ::endgroup::
